Workbook

Sheet RawData
A1: Company | B1: Bank | C1: Role | D1: Source | E1: Document | F1: Appointment
A2: AutoAI (Nanjing) Technology Co., Ltd. | B2: CLSA Limited | C2: Sponsor-Overall Coordinator | D2: https://www1.hkexnews.hk/app/sehk/2025/107497/documents/sehk25071000873.pdf | E2: OC Announcement - 10/07/2025 | F2: 27 June 2025
A3: AutoAI (Nanjing) Technology Co., Ltd. | B3: CMB International Capital Limited | C3: Overall Coordinator | D3: https://www1.hkexnews.hk/app/sehk/2025/107497/documents/sehk25071000873.pdf | E3: OC Announcement - 10/07/2025 | F3: 10 July 2025
A4: AutoAI (Nanjing) Technology Co., Ltd. | B4: SBI China Capital Financial Services Limited | C4: Overall Coordinator | D4: https://www1.hkexnews.hk/app/sehk/2025/107497/documents/sehk25071000873.pdf | E4: OC Announcement - 10/07/2025 | F4: 10 July 2025
A5: Qingdao Gon Technology Co., Ltd. | B5: China Merchants Securities (HK) Co., Limited | C5: Sponsor-Overall Coordinator | D5: https://www1.hkexnews.hk/app/sehk/2025/107485/documents/sehk25071000925.pdf | E5: OC Announcement - 10/07/2025 | F5: 26 June 2025
A6: Qingdao Gon Technology Co., Ltd. | B6: China International Capital Corporation Hong Kong Securities Limited | C6: Overall Coordinator | D6: https://www1.hkexnews.hk/app/sehk/2025/107485/documents/sehk25071000925.pdf | E6: OC Announcement - 10/07/2025 | F6: 10 July 2025
A7: Qingdao Gon Technology Co., Ltd. | B7: CLSA Limited | C7: Overall Coordinator | D7: https://www1.hkexnews.hk/app/sehk/2025/107485/documents/sehk25071000925.pdf | E7: OC Announcement - 10/07/2025 | F7: 10 July 2025
A8: Intsig Information Co., Ltd. | B8: China International Capital Corporation Hong Kong Securities Limited | C8: Sponsor-Overall Coordinator | D8: https://www1.hkexnews.hk/app/sehk/2025/107479/documents/sehk25070900940.pdf | E8: OC Announcement - 09/07/2025 | F8: 26 June 2025
A9: Intsig Information Co., Ltd. | B9: CLSA Limited | C9: Overall Coordinator | D9: https://www1.hkexnews.hk/app/sehk/2025/107479/documents/sehk25070900940.pdf | E9: OC Announcement - 09/07/2025 | F9: 9 July 2025
A10: Shanghai Longcheer Technology Co., Ltd. | B10: Citigroup Global Markets Asia Limited | C10: Sponsor-Overall Coordinator | D10: https://www1.hkexnews.hk/app/sehk/2025/107505/documents/sehk25070900720.pdf | E10: OC Announcement - 09/07/2025 | F10: 27 June 2025
A11: Shanghai Longcheer Technology Co., Ltd. | B11: Haitong International Securities Company Limited | C11: Sponsor-Overall Coordinator | D11: https://www1.hkexnews.hk/app/sehk/2025/107505/documents/sehk25070900720.pdf | E11: OC Announcement - 09/07/2025 | F11: 27 June 2025
A12: Shanghai Longcheer Technology Co., Ltd. | B12: Guotai Junan Securities (Hong Kong) Limited | C12: Sponsor-Overall Coordinator | D12: https://www1.hkexnews.hk/app/sehk/2025/107505/documents/sehk25070900720.pdf | E12: OC Announcement - 09/07/2025 | F12: 27 June 2025
... A129: Delton Technology (Guangzhou) Inc. | B129: Huatai Financial Holdings (Hong Kong) Limited | C129: Overall Coordinator | D129: https://www1.hkexnews.hk/app/sehk/2025/107433/documents/sehk25062500424.pdf | E129: OC Announcement - 25/06/2025 | F129: 25 June 2025
A130: Immvira Bioscience Inc. | B130: Citigroup Global Markets Asia Limited | C130: Overall Coordinator | E130: OC Announcement - 25/06/2025 | F130: 25 June 2025
A131: Immvira Bioscience Inc. | B131: China International Capital Corporation Hong Kong Securities Limited | C131: Overall Coordinator | D131: https://www1.hkexnews.hk/app/sehk/2025/107478/documents/sehk25062502251.pdf | E131: OC Announcement - 25/06/2025 | F131: 25 June 2025
A132: GigaDevice Semiconductor Inc. | B132: China International Capital Corporation Hong Kong Securities Limited | C132: Overall Coordinator | D132: https://www1.hkexnews.hk/app/sehk/2025/107462/documents/sehk25061901349.pdf | E132: OC Announcement - 23/06/2025 | F132: 23 June 2025
A133: GigaDevice Semiconductor Inc. | B133: Huatai Financial Holdings (Hong Kong) Limited | C133: Overall Coordinator | D133: https://www1.hkexnews.hk/app/sehk/2025/107462/documents/sehk25061901349.pdf | E133: OC Announcement - 23/06/2025 | F133: 23 June 2025
A134: PPLabs Technology Limited | B134: ICBC International Securities Limited | C134: Overall Coordinator | D134: https://www1.hkexnews.hk/app/sehk/2025/107464/documents/sehk25062001211.pdf | E134: OC Announcement - 20/06/2025 | F134: 20 June 2025
A135: PPLabs Technology Limited | B135: Shenwan Hongyuan Securities (H.K.) Limited | C135: Overall Coordinator | D135: https://www1.hkexnews.hk/app/sehk/2025/107464/documents/sehk25062001211.pdf | E135: OC Announcement - 20/06/2025 | F135: 20 June 2025
A136: Gpixel Changchun Microelectronics Inc. | B136: CLSA Limited | C136: Overall Coordinator | D136: https://www1.hkexnews.hk/app/sehk/2025/107461/documents/sehk25061901057.pdf | E136: OC Announcement - 19/06/2025 | F136: 19 June 2025
A137: Gpixel Changchun Microelectronics Inc. | B137: Guotai Junan Securities (Hong Kong) Limited | C137: Overall Coordinator | D137: https://www1.hkexnews.hk/app/sehk/2025/107461/documents/sehk25061901057.pdf | E137: OC Announcement - 19/06/2025 | F137: 19 June 2025
A138: Shanghai Able Digital Science&Tech Co., Ltd. | B138: ABCI Capital Limited | C138: Sole Overall Coordinator | D138: https://www1.hkexnews.hk/app/sehk/2025/107458/documents/sehk25061801700.pdf | E138: OC Announcement - 18/06/2025 | F138: 17 June 2025
A139: Beijing Haizhi Technology Group Co., Ltd. | B139: CMB International Capital Limited | C139: Overall Coordinator | D139: https://www1.hkexnews.hk/app/sehk/2025/107452/documents/sehk25061701306.pdf | E139: OC Announcement - 17/06/2025 | F139: 17 June 2025
A140: Beijing Haizhi Technology Group Co., Ltd. | B140: BOCI Asia Limited | C140: Overall Coordinator | D140: https://www1.hkexnews.hk/app/sehk/2025/107452/documents/sehk25061701306.pdf | E140: OC Announcement - 17/06/2025 | F140: 17 June 2025
A141: Beijing Haizhi Technology Group Co., Ltd. | B141: Shenwan Hongyuan Securities (H.K.) Limited | C141: Overall Coordinator | D141: https://www1.hkexnews.hk/app/sehk/2025/107452/documents/sehk25061701306.pdf | E141: OC Announcement - 17/06/2025 | F141: 17 June 2025
A142: EpimAb Biotherapeutics Inc. | B142: CLSA Limited | C142: Overall Coordinator | D142: https://www1.hkexnews.hk/app/sehk/2025/107454/documents/sehk25061701408.pdf | E142: OC Announcement - 17/06/2025 | F142: 17 June 2025
... A195: Worldwide Logistics Holding Inc. | B195: China Industrial Securities International Capital Limited | C195: Overall Coordinator | D195: https://www1.hkexnews.hk/app/sehk/2025/107399/documents/sehk25060900807.pdf | E195: OC Announcement - 09/06/2025 | F195: 9 June 2025
A196: Switchbot (Shenzhen) Co., Ltd. | B196: Guotai Junan Securities (Hong Kong) Limited | C196: Sponsor-Overall Coordinator | D196: https://www1.hkexnews.hk/app/sehk/2025/107426/documents/sehk25060800138.pdf | E196: OC Announcement - 08/06/2025 | F196: 45816
A197: Switchbot (Shenzhen) Co., Ltd. | B197: Huatai Financial Holdings (Hong Kong) Limited | C197: Sponsor-Overall Coordinator | D197: https://www1.hkexnews.hk/app/sehk/2025/107426/documents/sehk25060800138.pdf | E197: OC Announcement - 08/06/2025 | F197: 45816
A198: Beijing Sinotau International Pharmaceutical Technology Co., Ltd. | B198: China International Capital Corporation Hong Kong Securities Limited | C198: Overall Coordinator | D198: https://www1.hkexnews.hk/app/sehk/2025/107395/documents/sehk25060601346.pdf | E198: OC Announcement - 06/06/2025 | F198: 6 June 2025
A199: Beijing Sinotau International Pharmaceutical Technology Co., Ltd. | B199: CLSA Limited | C199: Overall Coordinator | D199: https://www1.hkexnews.hk/app/sehk/2025/107395/documents/sehk25060601346.pdf | E199: OC Announcement - 06/06/2025 | F199: 6 June 2025
A200: Beijing Sinotau International Pharmaceutical Technology Co., Ltd. | B200: GF Securities (Hong Kong) Brokerage Limited | C200: Overall Coordinator | D200: https://www1.hkexnews.hk/app/sehk/2025/107395/documents/sehk25060601346.pdf | E200: OC Announcement - 06/06/2025 | F200: 6 June 2025
A201: Beijing Sinotau International Pharmaceutical Technology Co., Ltd. | B201: DBS Asia Capital Limited | C201: Overall Coordinator | D201: https://www1.hkexnews.hk/app/sehk/2025/107395/documents/sehk25060601346.pdf | E201: OC Announcement - 06/06/2025 | F201: 6 June 2025
A202: Beijing Sinotau International Pharmaceutical Technology Co., Ltd. | B202: CMB International Capital Limited | C202: Overall Coordinator | D202: https://www1.hkexnews.hk/app/sehk/2025/107395/documents/sehk25060601346.pdf | E202: OC Announcement - 06/06/2025 | F202: 6 June 2025
A203: 52TOYS Development Co., Ltd. | B203: Citigroup Global Markets Asia Limited | C203: Sponsor-Overall Coordinator | D203: https://www1.hkexnews.hk/app/sehk/2025/107389/documents/sehk25060500514.pdf | E203: OC Announcement - 05/06/2025 | F203: 22 May 2025
A204: 52TOYS Development Co., Ltd. | B204: Huatai Financial Holdings (Hong Kong) Limited | C204: Sponsor-Overall Coordinator | D204: https://www1.hkexnews.hk/app/sehk/2025/107389/documents/sehk25060500514.pdf | E204: OC Announcement - 05/06/2025 | F204: 5 June 2025
A205: 52TOYS Development Co., Ltd. | B205: GF Securities (Hong Kong) Brokerage Limited | C205: Overall Coordinator | D205: https://www1.hkexnews.hk/app/sehk/2025/107389/documents/sehk25060500514.pdf | E205: OC Announcement - 05/06/2025 | F205: 4 June 2025
A206: SANY Heavy Industry Co., Ltd. | B206: CLSA Limited | C206: Sponsor-Overall Coordinator | D206: https://www1.hkexnews.hk/app/sehk/2025/107388/documents/sehk25060502412.pdf | E206: OC Announcement - 05/06/2025 | F206: 22 May 2025
A207: SANY Heavy Industry Co., Ltd. | B207: China International Capital Corporation Hong Kong Securities Limited | C207: Overall Coordinator | D207: https://www1.hkexnews.hk/app/sehk/2025/107388/documents/sehk25060502412.pdf | E207: OC Announcement - 05/06/2025 | F207: 5 June 2025
A208: Shenzhen Hipine Precision Technology Co., Ltd. | B208: Ping An Securities (Hong Kong) Company Limited | C208: Overall Coordinator | D208: https://www1.hkexnews.hk/app/sehk/2025/107421/documents/sehk25060302776.pdf | E208: OC Announcement - 04/06/2025 | F208: 45812
...

Sheet Bank Rankings
A1: Bank | B1: Total Mandates | C1: Sponsor Roles | D1: Lead Rate % | E1: Market Share %
A2: Shanxi Securities International Limited | B2: =COUNTIF(RawData!B:B,A2) -> 1 | C2: =COUNTIFS(RawData!B:B,A2,RawData!C:C,"*Sponsor*") -> 0 | D2: =IF(B2=0,0,C2/B2) -> 0 | E2: =B2/(COUNTA(RawData!A:A)-1) -> 0.0022172949
A3: Zero2IPO Securities Limited | B3: =COUNTIF(RawData!B:B,A3) -> 1 | C3: =COUNTIFS(RawData!B:B,A3,RawData!C:C,"*Sponsor*") -> 0 | D3: =IF(B3=0,0,C3/B3) -> 0 | E3: =B3/(COUNTA(RawData!A:A)-1) -> 0.0022172949
A4: ABCI Capital Limited | B4: =COUNTIF(RawData!B:B,A4) -> 19 | C4: =COUNTIFS(RawData!B:B,A4,RawData!C:C,"*Sponsor*") -> 5 | D4: =IF(B4=0,0,C4/B4) -> 0.26315789 | E4: =B4/(COUNTA(RawData!A:A)-1) -> 0.042128603
A5: BNP Paribas Securities (Asia) Limited | B5: =COUNTIF(RawData!B:B,A5) -> 5 | C5: =COUNTIFS(RawData!B:B,A5,RawData!C:C,"*Sponsor*") -> 2 | D5: =IF(B5=0,0,C5/B5) -> 0.4 | E5: =B5/(COUNTA(RawData!A:A)-1) -> 0.011086475
A6: BOCI Asia Limited | B6: =COUNTIF(RawData!B:B,A6) -> 10 | C6: =COUNTIFS(RawData!B:B,A6,RawData!C:C,"*Sponsor*") -> 1 | D6: =IF(B6=0,0,C6/B6) -> 0.1 | E6: =B6/(COUNTA(RawData!A:A)-1) -> 0.022172949
A7: BOCOM International Securities Limited | B7: =COUNTIF(RawData!B:B,A7) -> 5 | C7: =COUNTIFS(RawData!B:B,A7,RawData!C:C,"*Sponsor*") -> 1 | D7: =IF(B7=0,0,C7/B7) -> 0.2 | E7: =B7/(COUNTA(RawData!A:A)-1) -> 0.011086475
A8: CCB International Capital Limited | B8: =COUNTIF(RawData!B:B,A8) -> 24 | C8: =COUNTIFS(RawData!B:B,A8,RawData!C:C,"*Sponsor*") -> 1 | D8: =IF(B8=0,0,C8/B8) -> 0.041666667 | E8: =B8/(COUNTA(RawData!A:A)-1) -> 0.053215078
A9: CLSA Limited | B9: =COUNTIF(RawData!B:B,A9) -> 69 | C9: =COUNTIFS(RawData!B:B,A9,RawData!C:C,"*Sponsor*") -> 22 | D9: =IF(B9=0,0,C9/B9) -> 0.31884058 | E9: =B9/(COUNTA(RawData!A:A)-1) -> 0.15299335
A10: CMB International Capital Limited | B10: =COUNTIF(RawData!B:B,A10) -> 27 | C10: =COUNTIFS(RawData!B:B,A10,RawData!C:C,"*Sponsor*") -> 3 | D10: =IF(B10=0,0,C10/B10) -> 0.11111111 | E10: =B10/(COUNTA(RawData!A:A)-1) -> 0.059866962
A11: CMBC Securities Company Limited | B11: =COUNTIF(RawData!B:B,A11) -> 6 | C11: =COUNTIFS(RawData!B:B,A11,RawData!C:C,"*Sponsor*") -> 2 | D11: =IF(B11=0,0,C11/B11) -> 0.33333333 | E11: =B11/(COUNTA(RawData!A:A)-1) -> 0.013303769
A12: China Everbright Securities (HK) Limited | B12: =COUNTIF(RawData!B:B,A12) -> 2 | C12: =COUNTIFS(RawData!B:B,A12,RawData!C:C,"*Sponsor*") -> 1 | D12: =IF(B12=0,0,C12/B12) -> 0.5 | E12: =B12/(COUNTA(RawData!A:A)-1) -> 0.0044345898
A13: China Galaxy International Securities (Hong Kong) Co., Limited | B13: =COUNTIF(RawData!B:B,A13) -> 7 | C13: =COUNTIFS(RawData!B:B,A13,RawData!C:C,"*Sponsor*") -> 0 | D13: =IF(B13=0,0,C13/B13) -> 0 | E13: =B13/(COUNTA(RawData!A:A)-1) -> 0.015521064
... A59: Zhongtai International Securities Limited | B59: =COUNTIF(RawData!B:B,A59) -> 4 | C59: =COUNTIFS(RawData!B:B,A59,RawData!C:C,"*Sponsor*") -> 0 | D59: =IF(B59=0,0,C59/B59) -> 0 | E59: =B59/(COUNTA(RawData!A:A)-1) -> 0.0088691796
A62: Note: Sort by 'Total Mandates' column to see most active banks

Sheet Key Banks Analysis
A1: KEY BANKS PARTNERSHIP ANALYSIS
A3: Huatai
A4: Total Deals: | B4: =COUNTIF(RawData!B:B,"Huatai Financial Holdings (Hong Kong) Limited") -> 29
A5: As Sponsor: | B5: =COUNTIFS(RawData!B:B,"Huatai Financial Holdings (Hong Kong) Limited",RawData!C:C,"*Sponsor*") -> 10
A7: Top Partners:
A8: China International Capital Corporation Hong Kong Securities Limited | B8: 12 | C8: deals together
A9: CLSA Limited | B9: 9 | C9: deals together
A10: ABCI Capital Limited | B10: 5 | C10: deals together
A11: CCB International Capital Limited | B11: 5 | C11: deals together
A12: GF Securities (Hong Kong) Brokerage Limited | B12: 5 | C12: deals together
A15: Morgan Stanley
A16: Total Deals: | B16: =COUNTIF(RawData!B:B,"Morgan Stanley Asia Limited") -> 4
A17: As Sponsor: | B17: =COUNTIFS(RawData!B:B,"Morgan Stanley Asia Limited",RawData!C:C,"*Sponsor*") -> 1
A19: Top Partners:
A20: ABCI Capital Limited | B20: 2 | C20: deals together
A21: Huatai Financial Holdings (Hong Kong) Limited | B21: 2 | C21: deals together
A22: CLSA Limited | B22: 2 | C22: deals together
A23: BOCI Asia Limited | B23: 1 | C23: deals together
A24: Deutsche Bank AG | B24: 1 | C24: deals together
A27: Bank of America/Merrill Lynch
A28: Total Deals: | B28: =COUNTIF(RawData!B:B,"Merrill Lynch (Asia Pacific) Limited") -> 2
A29: As Sponsor: | B29: =COUNTIFS(RawData!B:B,"Merrill Lynch (Asia Pacific) Limited",RawData!C:C,"*Sponsor*") -> 0
A31: Top Partners:
A32: Haitong International Securities Company Limited | B32: 1 | C32: deals together
A33: UBS AG Hong Kong Branch | B33: 1 | C33: deals together
A34: Huatai Financial Holdings (Hong Kong) Limited | B34: 1 | C34: deals together
A35: Goldman Sachs (Asia) L.L.C. | B35: 1 | C35: deals together
A36: J.P. Morgan Securities (Asia Pacific) Limited | B36: 1 | C36: deals together
A39: STRATEGIC INSIGHTS:
A41: • ABCI Capital works with both Huatai (5 deals) and Morgan Stanley (2 deals) - potential bridge
A42: • CLSA and CICC dominate the market with 127 combined mandates (28% market share)
A43: • Huatai's strongest partnership is with CICC (12 deals) - leverage this relationship
A44: • Morgan Stanley and Bank of America have limited presence - opportunity for growth
A45: • 'Sponsor' roles indicate leadership position - 23% of all roles

Sheet Partnership Matrix
A1: RECURRING PARTNERSHIPS (3+ DEALS)
A3: Bank 1 | B3: Bank 2 | C3: Deal Count | D3: Key Bank Involved
A4: CLSA Limited | B4: China International Capital Corporation Hong Kong Securities Limited | C4: 19
A5: CLSA Limited | B5: CMB International Capital Limited | C5: 13
A6: China International Capital Corporation Hong Kong Securities Limited | B6: Huatai Financial Holdings (Hong Kong) Limited | C6: 12 | D6: Huatai
A7: CMB International Capital Limited | B7: China International Capital Corporation Hong Kong Securities Limited | C7: 10
A8: CLSA Limited | B8: Huatai Financial Holdings (Hong Kong) Limited | C8: 9 | D8: Huatai
A9: CLSA Limited | B9: GF Securities (Hong Kong) Brokerage Limited | C9: 8
A10: CLSA Limited | B10: Haitong International Securities Company Limited | C10: 7
A11: CCB International Capital Limited | B11: CLSA Limited | C11: 7
A12: ABCI Capital Limited | B12: CLSA Limited | C12: 6
A13: China International Capital Corporation Hong Kong Securities Limited | B13: GF Securities (Hong Kong) Brokerage Limited | C13: 6
A14: ABCI Capital Limited | B14: CCB International Capital Limited | C14: 6
A15: CLSA Limited | B15: Guotai Junan Securities (Hong Kong) Limited | C15: 6
A16: CLSA Limited | B16: China Securities (International) Corporate Finance Company Limited | C16: 6
A17: China International Capital Corporation Hong Kong Securities Limited | B17: Deutsche Bank AG, Hong Kong Branch | C17: 6
A18: CLSA Limited | B18: Deutsche Bank AG, Hong Kong Branch | C18: 5
A19: ABCI Capital Limited | B19: Huatai Financial Holdings (Hong Kong) Limited | C19: 5 | D19: Huatai
A20: CCB International Capital Limited | B20: Huatai Financial Holdings (Hong Kong) Limited | C20: 5 | D20: Huatai
A21: GF Securities (Hong Kong) Brokerage Limited | B21: Huatai Financial Holdings (Hong Kong) Limited | C21: 5 | D21: Huatai
A22: CMB International Capital Limited | B22: China Securities (International) Corporate Finance Company Limited | C22: 5
A23: China International Capital Corporation Hong Kong Securities Limited | B23: China Merchants Securities (HK) Co., Limited | C23: 4
